Workbook
Name AR5_Ratio: [1]Lookups!$J$33:$K$37
Name AR5_TruFal: [1]Lookups!$G$33:$H$73

Sheet gDP
A1: Data Source | B1: World Development Indicators
A3: Last Updated Date | B3: 45609
A5: Country Name | B5: Country Code | C5: Indicator Name | D5: Indicator Code | E5: 1960 | F5: 1961 | G5: 1962 | H5: 1963 | I5: 1964 | J5: 1965 | K5: 1966 | L5: 1967 | M5: 1968 | N5: 1969 | O5: 1970 | P5: 1971 | Q5: 1972 | R5: 1973 | S5: 1974 | T5: 1975 | U5: 1976 | V5: 1977 | W5: 1978 | X5: 1979 | Y5: 1980 | Z5: 1981 | AA5: 1982 | AB5: 1983 | AC5: 1984 | AD5: 1985 | AE5: 1986 | AF5: 1987 | AG5: 1988 | AH5: 1989 | AI5: 1990 | AJ5: 1991 | AK5: 1992 | AL5: 1993 | AM5: 1994 | AN5: 1995 | AO5: 1996 | AP5: 1997 | AQ5: 1998 | AR5: 1999 | AS5: 2000 | AT5: 2001 | AU5: 2002 | AV5: 2003 | AW5: 2004 | AX5: 2005 | AY5: 2006 | AZ5: 2007 | BA5: 2008 | BB5: 2009 | BC5: 2010 | BD5: 2011 | BE5: 2012 | BF5: 2013 | BG5: 2014 | BH5: 2015 | BI5: 2016 | BJ5: 2017 | BK5: 2018 | BL5: 2019 | BM5: 2020 | BN5: 2021 | BO5: 2022 | BP5: 2023
A6: Aruba | B6: ABW | C6: GDP (current US$) | D6: NY.GDP.MKTP.CD | AE6: 4.0558659e+08 | AF6: 4.877095e+08 | AG6: 5.9664804e+08 | AH6: 6.9553073e+08 | AI6: 7.6480447e+08 | AJ6: 8.7206704e+08 | AK6: 9.5865922e+08 | AL6: 1.0832402e+09 | AM6: 1.2458101e+09 | AN6: 1.3206704e+09 | AO6: 1.3798883e+09 | AP6: 1.5318436e+09 | AQ6: 1.6653631e+09 | AR6: 1.722905e+09 | AS6: 1.8734525e+09 | AT6: 1.896457e+09 | AU6: 1.9618436e+09 | AV6: 2.0441117e+09 | AW6: 2.2548307e+09 | AX6: 2.3600173e+09 | AY6: 2.4697827e+09 | AZ6: 2.6776413e+09 | BA6: 2.8430246e+09 | BB6: 2.5537933e+09 | BC6: 2.4535972e+09 | BD6: 2.6378592e+09 | BE6: 2.6152084e+09 | BF6: 2.7278497e+09 | BG6: 2.7908497e+09 | BH6: 2.9629073e+09 | BI6: 2.9836352e+09 | BJ6: 3.0924291e+09 | BK6: 3.2761844e+09 | BL6: 3.3957989e+09 | BM6: 2.5589063e+09 | BN6: 3.1031841e+09 | BO6: 3.5447078e+09
A7: Africa Eastern and Southern | B7: AFE | C7: GDP (current US$) | D7: NY.GDP.MKTP.CD | E7: 2.1216962e+10 | F7: 2.2307471e+10 | G7: 2.3702472e+10 | H7: 2.5779377e+10 | I7: 2.8049537e+10 | J7: 3.037491e+10 | K7: 3.3049155e+10 | L7: 3.5933757e+10 | M7: 3.8749865e+10 | N7: 4.2964345e+10 | O7: 4.3702318e+10 | P7: 4.7632994e+10 | Q7: 5.1627512e+10 | R7: 6.6610918e+10 | S7: 8.1658052e+10 | T7: 8.6883553e+10 | U7: 8.8290756e+10 | V7: 9.8868135e+10 | W7: 1.1080241e+11 | X7: 1.2978097e+11 | Y7: 1.6816516e+11 | Z7: 1.777501e+11 | AA7: 1.6930277e+11 | AB7: 1.7989783e+11 | AC7: 1.662081e+11 | AD7: 1.4324952e+11 | AE7: 1.5479261e+11 | AF7: 1.8581246e+11 | AG7: 2.0209261e+11 | AH7: 2.144735e+11 | AI7: 2.5121184e+11 | AJ7: 2.735426e+11 | AK7: 2.3943317e+11 | AL7: 2.4027139e+11 | AM7: 2.4356481e+11 | AN7: 2.7343306e+11 | AO7: 2.7251934e+11 | AP7: 2.8840528e+11 | AQ7: 2.6883364e+11 | AR7: 2.6542929e+11 | AS7: 2.8720165e+11 | AT7: 2.6099223e+11 | AU7: 2.6781504e+11 | AV7: 3.5571637e+11 | AW7: 4.4269619e+11 | AX7: 5.1666107e+11 | AY7: 5.8024075e+11 | AZ7: 6.655987e+11 | BA7: 7.1350211e+11 | BB7: 7.1548533e+11 | BC7: 8.4940966e+11 | BD7: 9.4543915e+11 | BE7: 9.5267559e+11 | BF7: 9.6334728e+11 | BG7: 9.7968966e+11 | BH7: 8.9929568e+11 | BI7: 8.2982996e+11 | BJ7: 9.4010548e+11 | BK7: 1.0127193e+12 | BL7: 1.0065273e+12 | BM7: 9.2907409e+11 | BN7: 1.0867722e+12 | BO7: 1.1839621e+12 | BP7: 1.236163e+12
A8: Afghanistan | B8: AFG | C8: GDP (current US$) | D8: NY.GDP.MKTP.CD | AS8: 3.5214181e+09 | AT8: 2.8135718e+09 | AU8: 3.8257014e+09 | AV8: 4.5209468e+09 | AW8: 5.2248967e+09 | AX8: 6.2032565e+09 | AY8: 6.9717583e+09 | AZ8: 9.7478862e+09 | BA8: 1.0109297e+10 | BB8: 1.2416153e+10 | BC8: 1.5856669e+10 | BD8: 1.7805098e+10 | BE8: 1.990733e+10 | BF8: 2.0146417e+10 | BG8: 2.0497129e+10 | BH8: 1.9134222e+10 | BI8: 1.8116572e+10 | BJ8: 1.8753456e+10 | BK8: 1.8053223e+10 | BL8: 1.8799444e+10 | BM8: 1.9955929e+10 | BN8: 1.4266499e+10 | BO8: 1.4502158e+10
A9: Africa Western and Central | B9: AFW | C9: GDP (current US$) | D9: NY.GDP.MKTP.CD | E9: 1.1884128e+10 | F9: 1.2685662e+10 | G9: 1.3606829e+10 | H9: 1.4439975e+10 | I9: 1.5769108e+10 | J9: 1.693448e+10 | K9: 1.8048039e+10 | L9: 1.6495768e+10 | M9: 1.7022696e+10 | N9: 1.9301308e+10 | O9: 2.6697108e+10 | P9: 2.4507116e+10 | Q9: 2.9493915e+10 | R9: 3.6902673e+10 | S9: 4.9688194e+10 | T9: 5.7280847e+10 | U9: 6.838632e+10 | V9: 7.1790696e+10 | W9: 7.87791e+10 | X9: 9.6682239e+10 | Y9: 1.2050108e+11 | Z9: 2.1691103e+11 | AA9: 1.9591794e+11 | AB9: 1.5122276e+11 | AC9: 1.3121816e+11 | AD9: 1.3780292e+11 | AE9: 1.09237e+11 | AF9: 1.1229477e+11 | AG9: 1.1122715e+11 | AH9: 1.0393437e+11 | AI9: 1.2371132e+11 | AJ9: 1.29942e+11 | AK9: 1.2459939e+11 | AL9: 1.2973255e+11 | AM9: 1.347769e+11 | AN9: 2.0717699e+11 | AO9: 2.6260091e+11 | AP9: 2.7574224e+11 | AQ9: 2.9615244e+11 | AR9: 1.3946835e+11 | AS9: 1.4214008e+11 | AT9: 1.4945186e+11 | AU9: 1.7869244e+11 | AV9: 2.0698205e+11 | AW9: 2.5610064e+11 | AX9: 3.1240932e+11 | AY9: 3.9708879e+11 | AZ9: 4.6568351e+11 | BA9: 5.6793796e+11 | BB9: 5.0855258e+11 | BC9: 5.9869771e+11 | BD9: 6.8223332e+11 | BE9: 7.3779965e+11 | BF9: 8.3416061e+11 | BG9: 8.9458544e+11 | BH9: 7.6936732e+11 | BI9: 6.9218109e+11 | BJ9: 6.8575016e+11 | BK9: 7.6818959e+11 | BL9: 8.2393363e+11 | BM9: 7.8714672e+11 | BN9: 8.4599305e+11 | BO9: 8.7714081e+11 | BP9: 7.9658616e+11
A10: Angola | B10: AGO | C10: GDP (current US$) | D10: NY.GDP.MKTP.CD | AL10: 5880000000 | AM10: 4.4320261e+09 | AN10: 5.5386573e+09 | AO10: 6.5354584e+09 | AP10: 7.6754238e+09 | AQ10: 6.5063872e+09 | AR10: 6.1529233e+09 | AS10: 9.129595e+09 | AT10: 8.9360791e+09 | AU10: 1.5285592e+10 | AV10: 1.7812705e+10 | AW10: 2.3552058e+10 | AX10: 3.6970901e+10 | AY10: 5.2381025e+10 | AZ10: 6.5266415e+10 | BA10: 8.8538665e+10 | BB10: 7.0307196e+10 | BC10: 8.3799474e+10 | BD10: 1.1178975e+11 | BE10: 1.2805292e+11 | BF10: 1.3233911e+11 | BG10: 1.359668e+11 | BH10: 9.0496421e+10 | BI10: 5.2761617e+10 | BJ10: 7.3690155e+10 | BK10: 7.9450688e+10 | BL10: 7.0897963e+10 | BM10: 4.8501561e+10 | BN10: 6.650513e+10 | BO10: 1.0439975e+11 | BP10: 8.4722958e+10
A11: Albania | B11: ALB | C11: GDP (current US$) | D11: NY.GDP.MKTP.CD | AC11: 1.857338e+09 | AD11: 1.8970501e+09 | AE11: 2097326250 | AF11: 2080796250 | AG11: 2051236250 | AH11: 2253090000 | AI11: 2028553750 | AJ11: 1.099559e+09 | AK11: 6.5217499e+08 | AL11: 1.1853155e+09 | AM11: 1.8809509e+09 | AN11: 2.3927649e+09 | AO11: 3.1996408e+09 | AP11: 2.258514e+09 | AQ11: 2.5459645e+09 | AR11: 3.2121217e+09 | AS11: 3.4803553e+09 | AT11: 3.9221008e+09 | AU11: 4.3480682e+09 | AV11: 5.6114963e+09 | AW11: 7.1846858e+09 | AX11: 8.0520772e+09 | AY11: 8.896075e+09 | AZ11: 1.0677325e+10 | BA11: 1.2881353e+10 | BB11: 1.2044206e+10 | BC11: 1.1926927e+10 | BD11: 1.289076e+10 | BE11: 1.2319834e+10 | BF11: 1.2776224e+10 | BG11: 1.3228148e+10 | BH11: 1.1386853e+10 | BI11: 1.18612e+10 | BJ11: 1.3019726e+10 | BK11: 1.5156424e+10 | BL11: 1.5401826e+10 | BM11: 1.5162734e+10 | BN11: 1.7930565e+10 | BO11: 1.8916379e+10 | BP11: 2.2977678e+10
A12: Andorra | B12: AND | C12: GDP (current US$) | D12: NY.GDP.MKTP.CD | O12: 78617711 | P12: 89406608 | Q12: 1.134144e+08 | R12: 1.5084164e+08 | S12: 1.8655708e+08 | T12: 2.2011257e+08 | U12: 2.2728385e+08 | V12: 2.539979e+08 | W12: 3.0802026e+08 | X12: 4.1154875e+08 | Y12: 4.4637778e+08 | Z12: 3.8898327e+08 | AA12: 3.7591474e+08 | AB12: 3.2785004e+08 | AC12: 3.3007308e+08 | AD12: 3.4674271e+08 | AE12: 4.8199601e+08 | AF12: 6.1129992e+08 | AG12: 7.2142594e+08 | AH12: 7.9548958e+08 | AI12: 1.0289897e+09 | AJ12: 1.1068914e+09 | AK12: 1.209992e+09 | AL12: 1.0070903e+09 | AM12: 1.0175441e+09 | AN12: 1.1787453e+09 | AO12: 1.2240241e+09 | AP12: 1.1806456e+09 | AQ12: 1.211954e+09 | AR12: 1.2402951e+09 | AS12: 1.4326062e+09 | AT12: 1.5482658e+09 | AU12: 1.7642798e+09 | AV12: 2.3669418e+09 | AW12: 2.9002453e+09 | AX12: 3.1610841e+09 | AY12: 3.459338e+09 | AZ12: 3.9576254e+09 | BA12: 4.1023194e+09 | BB12: 3.6889763e+09 | BC12: 3.4499257e+09 | BD12: 3.6291336e+09 | BE12: 3.1886528e+09 | BF12: 3.193513e+09 | BG12: 3.2716856e+09 | BH12: 2.7898813e+09 | BI12: 2.8966105e+09 | BJ12: 3.0001621e+09 | BK12: 3.2184199e+09 | BL12: 3.1551493e+09 | BM12: 2.8910011e+09 | BN12: 3.324683e+09 | BO12: 3.380602e+09 | BP12: 3.7276736e+09
A13: Arab World | B13: ARB | C13: GDP (current US$) | D13: NY.GDP.MKTP.CD | J13: 2.6772088e+10 | K13: 2.8352061e+10 | L13: 3.0601968e+10 | M13: 3.4974202e+10 | N13: 3.8564894e+10 | O13: 4.3095586e+10 | P13: 4.9931741e+10 | Q13: 5.9972469e+10 | R13: 7.9132917e+10 | S13: 1.5220208e+11 | T13: 1.681736e+11 | U13: 2.100121e+11 | V13: 2.422925e+11 | W13: 2.6542751e+11 | X13: 3.5814057e+11 | Y13: 4.8644098e+11 | Z13: 4.9494936e+11 | AA13: 4.6311678e+11 | AB13: 4.3750279e+11 | AC13: 4.4021396e+11 | AD13: 4.3289957e+11 | AE13: 4.055025e+11 | AF13: 4.3128883e+11 | AG13: 4.2941386e+11 | AH13: 4.5740211e+11 | AI13: 6.4009092e+11 | AJ13: 4.6637435e+11 | AK13: 4.6606266e+11 | AL13: 4.771896e+11 | AM13: 4.9808376e+11 | AN13: 5.2656085e+11 | AO13: 5.6878541e+11 | AP13: 6.1239463e+11 | AQ13: 5.9674229e+11 | AR13: 6.6317606e+11 | AS13: 7.6065953e+11 | AT13: 7.4197482e+11 | AU13: 7.4372648e+11 | AV13: 8.269765e+11 | AW13: 9.8370079e+11 | AX13: 1.2055959e+12 | AY13: 1.4341092e+12 | AZ13: 1.668426e+12 | BA13: 2.1091718e+12 | BB13: 1.8227838e+12 | BC13: 2.1542523e+12 | BD13: 2.5598552e+12 | BE13: 2.7937757e+12 | BF13: 2.857872e+12 | BG13: 2.9050759e+12 | BH13: 2.5441363e+12 | BI13: 2.4999659e+12 | BJ13: 2.5710537e+12 | BK13: 2.8655436e+12 | BL13: 2.8986687e+12 | BM13: 2.5765533e+12 | BN13: 2.9691168e+12 | BO13: 3.6136824e+12 | BP13: 3.4915169e+12
A14: United Arab Emirates | B14: ARE | C14: GDP (current US$) | D14: NY.GDP.MKTP.CD | O14: 6.859867e+08 | P14: 9.398936e+08 | Q14: 1.4150869e+09 | R14: 4.2312436e+09 | S14: 1.1651506e+10 | T14: 1.4720728e+10 | U14: 1.9213159e+10 | V14: 2.4871775e+10 | W14: 2.3775764e+10 | X14: 3.122566e+10 | Y14: 4.359916e+10 | Z14: 4.9333424e+10 | AA14: 4.6622719e+10 | AB14: 4.2803323e+10 | AC14: 4.1807954e+10 | AD14: 4.060365e+10 | AE14: 3.3943612e+10 | AF14: 3.6384909e+10 | AG14: 3.6275674e+10 | AH14: 4.1464996e+10 | AI14: 5.0701444e+10 | AJ14: 5.1552166e+10 | AK14: 5.4239172e+10 | AL14: 5.562517e+10 | AM14: 5.9305094e+10 | AN14: 6.5743667e+10 | AO14: 7.3571234e+10 | AP14: 7.8839008e+10 | AQ14: 7.5674336e+10 | AR14: 8.4445473e+10 | AS14: 1.0433737e+11 | AT14: 1.0331164e+11 | AU14: 1.098162e+11 | AV14: 1.2434636e+11 | AW14: 1.4782437e+11 | AX14: 1.8061747e+11 | AY14: 2.2211654e+11 | AZ14: 2.5791613e+11 | BA14: 3.1547462e+11 | BB14: 2.5354736e+11 | BC14: 3.0018905e+11 | BD14: 3.6083274e+11 | BE14: 3.8461013e+11 | BF14: 4.0021853e+11 | BG14: 4.1410537e+11 | BH14: 3.7027547e+11 | BI14: 3.6925533e+11 | BJ14: 3.905168e+11 | BK14: 4.2704943e+11 | BL14: 4.1798972e+11 | BM14: 3.4947302e+11 | BN14: 4.1517879e+11 | BO14: 5.0706397e+11 | BP14: 5.0417345e+11
A15: Argentina | B15: ARG | C15: GDP (current US$) | D15: NY.GDP.MKTP.CD | AB15: 109490000000 | AC15: 1.1298857e+11 | AD15: 8.8416667e+10 | AE15: 1.0621383e+11 | AF15: 1.0902944e+11 | AG15: 126928000000 | AH15: 7.6629658e+10 | AI15: 1.4135265e+11 | AJ15: 1.8971998e+11 | AK15: 2.2877892e+11 | AL15: 2.3674172e+11 | AM15: 257440000000 | AN15: 258031750000 | AO15: 272149750000 | AP15: 292859000000 | AQ15: 298948250000 | AR15: 283523000000 | AS15: 284203750000 | AT15: 268696750000 | AU15: 9.7724004e+10 | AV15: 1.2758697e+11 | AW15: 1.6465793e+11 | AX15: 1.987371e+11 | AY15: 2.3255726e+11 | AZ15: 2.8753051e+11 | BA15: 3.6155804e+11 | BB15: 3.3297648e+11 | BC15: 4.2362742e+11 | BD15: 5.3015812e+11 | BE15: 5.4598238e+11 | BF15: 5.5202514e+11 | BG15: 5.2631967e+11 | BH15: 5.9474929e+11 | BI15: 5.5753232e+11 | BJ15: 6.4362839e+11 | BK15: 5.2481989e+11 | BL15: 4.4775468e+11 | BM15: 3.8574051e+11 | BN15: 4.8790257e+11 | BO15: 6.3113338e+11 | BP15: 6.4059141e+11
A16: Armenia | B16: ARM | C16: GDP (current US$) | D16: NY.GDP.MKTP.CD | AI16: 2.2568634e+09 | AJ16: 2.0698701e+09 | AK16: 1.2728355e+09 | AL16: 1.2013128e+09 | AM16: 1.3151586e+09 | AN16: 1.4683174e+09 | AO16: 1.5969689e+09 | AP16: 1.6394924e+09 | AQ16: 1.8937264e+09 | AR16: 1.8454822e+09 | AS16: 1.9115637e+09 | AT16: 2.1184679e+09 | AU16: 2.376335e+09 | AV16: 2.807061e+09 | AW16: 3.5766152e+09 | AX16: 4.9004695e+09 | AY16: 6.3844521e+09 | AZ16: 9.2063013e+09 | BA16: 1.1662041e+10 | BB16: 8.6479371e+09 | BC16: 9.2602858e+09 | BD16: 1.0142112e+10 | BE16: 1.0619321e+10 | BF16: 1.1121464e+10 | BG16: 1.1609513e+10 | BH16: 1.0553338e+10 | BI16: 1.0546136e+10 | BJ16: 1.1527459e+10 | BK16: 1.2457941e+10 | BL16: 1.3619291e+10 | BM16: 1.2641699e+10 | BN16: 1.3878909e+10 | BO16: 1.9513475e+10 | BP16: 2.4212135e+10
A17: American Samoa | B17: ASM | C17: GDP (current US$) | D17: NY.GDP.MKTP.CD | AU17: 512000000 | AV17: 524000000 | AW17: 509000000 | AX17: 500000000 | AY17: 493000000 | AZ17: 518000000 | BA17: 560000000 | BB17: 675000000 | BC17: 573000000 | BD17: 570000000 | BE17: 640000000 | BF17: 638000000 | BG17: 643000000 | BH17: 673000000 | BI17: 671000000 | BJ17: 612000000 | BK17: 639000000 | BL17: 647000000 | BM17: 721000000 | BN17: 750000000 | BO17: 871000000
A18: Antigua and Barbuda | B18: ATG | C18: GDP (current US$) | D18: NY.GDP.MKTP.CD | V18: 77496296 | W18: 88033333 | X18: 1.0958519e+08 | Y18: 1.3244074e+08 | Z18: 1.4937778e+08 | AA18: 1.6642593e+08 | AB18: 1.8484815e+08 | AC18: 2.1219259e+08 | AD18: 2.4634444e+08 | AE18: 2.9753704e+08 | AF18: 3.4684074e+08 | AG18: 4.1137407e+08 | AH18: 4.5514815e+08 | AI18: 4.7869259e+08 | AJ18: 5.0430741e+08 | AK18: 5.251037e+08 | AL18: 5.6563333e+08 | AM18: 6.2505185e+08 | AN18: 6.1601481e+08 | AO18: 6.7911111e+08 | AP18: 7.3439259e+08 | AQ18: 7.8976296e+08 | AR18: 8.3551481e+08 | AS18: 9.0055185e+08 | AT18: 8.7751481e+08 | AU18: 8.9798889e+08 | AV18: 9.4795556e+08 | AW18: 1.0261815e+09 | AX18: 1.1437148e+09 | AY18: 1.3035481e+09 | AZ18: 1487300000 | BA18: 1.5575407e+09 | BB18: 1.3864444e+09 | BC18: 1.2982556e+09 | BD18: 1.281337e+09 | BE18: 1.3271074e+09 | BF18: 1.3254259e+09 | BG18: 1.3788296e+09 | BH18: 1.4377556e+09 | BI18: 1.4896926e+09 | BJ18: 1.5311519e+09 | BK18: 1.6615296e+09 | BL18: 1.7253519e+09 | BM18: 1.4107963e+09 | BN18: 1.6013667e+09 | BO18: 1.8677333e+09 | BP18: 2.0330852e+09
A19: Australia | B19: AUS | C19: GDP (current US$) | D19: NY.GDP.MKTP.CD | E19: 1.8606563e+10 | F19: 1.9682883e+10 | G19: 1.9922563e+10 | H19: 2.1539843e+10 | I19: 2.3801124e+10 | J19: 2.5976164e+10 | K19: 2.7307844e+10 | L19: 3.0442725e+10 | M19: 3.2714085e+10 | N19: 3.6683366e+10 | O19: 4.1333607e+10 | P19: 4.5216647e+10 | Q19: 5.2040888e+10 | R19: 6.3830878e+10 | S19: 8.8963891e+10 | T19: 9.7303018e+10 | U19: 1.0505936e+11 | V19: 1.1034985e+11 | W19: 1.1849163e+11 | X19: 1.3489833e+11 | Y19: 1.4998552e+11 | Z19: 1.7689307e+11 | AA19: 1.940384e+11 | AB19: 1.7726542e+11 | AC19: 1.93519e+11 | AD19: 1.8063713e+11 | AE19: 1.8247552e+11 | AF19: 1.8948716e+11 | AG19: 2.3615404e+11 | AH19: 2.9987184e+11 | AI19: 3.1142051e+11 | AJ19: 3.2596669e+11 | AK19: 3.2551846e+11 | AL19: 3.121283e+11 | AM19: 3.2280249e+11 | AN19: 3.6816602e+11 | AO19: 4.0134188e+11 | AP19: 4.3564261e+11 | AQ19: 3.9967442e+11 | AR19: 3.8965221e+11 | AS19: 4.1616782e+11 | AT19: 3.796293e+11 | AU19: 3.957887e+11 | AV19: 4.6773908e+11 | AW19: 6.1465998e+11 | AX19: 6.956929e+11 | AY19: 7.4841756e+11 | AZ19: 8.5500746e+11 | BA19: 1.0561124e+12 | BB19: 9.2876212e+11 | BC19: 1.1488902e+12 | BD19: 1.3987013e+12 | BE19: 1.5476498e+12 | BF19: 1.5773018e+12 | BG19: 1.4685977e+12 | BH19: 1.3517689e+12 | BI19: 1.2075809e+12 | BJ19: 1326882104817 | BK19: 1.4297337e+12 | BL19: 1.3946713e+12 | BM19: 1.3303815e+12 | BN19: 1.5590338e+12 | BO19: 1.6929566e+12 | BP19: 1.7238272e+12
A20: Austria | B20: AUT | C20: GDP (current US$) | D20: NY.GDP.MKTP.CD | E20: 6.6501339e+09 | F20: 7.3754546e+09 | G20: 7.8236868e+09 | H20: 8.4471368e+09 | I20: 9.2498791e+09 | J20: 1.0081146e+10 | K20: 1.0982543e+10 | L20: 1.168032e+10 | M20: 1.2549017e+10 | N20: 1.3701141e+10 | O20: 1.5373006e+10 | P20: 1.7858486e+10 | Q20: 2.2059612e+10 | R20: 2.9515468e+10 | S20: 3.51893e+10 | T20: 4.0059207e+10 | U20: 4.2959976e+10 | V20: 5.1545759e+10 | W20: 6.2052259e+10 | X20: 7.3937297e+10 | Y20: 8.2058913e+10 | Z20: 7.1034228e+10 | AA20: 7.1275288e+10 | AB20: 7.2121017e+10 | AC20: 6.7985345e+10 | AD20: 6.9386774e+10 | AE20: 9.9036165e+10 | AF20: 1.2416844e+11 | AG20: 1.333394e+11 | AH20: 1.3310581e+11 | AI20: 1.6646339e+11 | AJ20: 1.7379418e+11 | AK20: 1.9507813e+11 | AL20: 1.9037972e+11 | AM20: 2.0353524e+11 | AN20: 2.4103828e+11 | AO20: 2.3725095e+11 | AP20: 2.1279035e+11 | AQ20: 2.182599e+11 | AR20: 2.1725915e+11 | AS20: 1.9728963e+11 | AT20: 1.9750877e+11 | AU20: 2.1439487e+11 | AV20: 2.6227363e+11 | AW20: 3.0145756e+11 | AX20: 3.1609227e+11 | AY20: 3.3628006e+11 | AZ20: 3.8918557e+11 | BA20: 4.3205194e+11 | BB20: 4.0175874e+11 | BC20: 3.9227511e+11 | BD20: 4.3168522e+11 | BE20: 4.0940182e+11 | BF20: 4.3019098e+11 | BG20: 4.4258482e+11 | BH20: 3.8197115e+11 | BI20: 3.9583735e+11 | BJ20: 4.1726115e+11 | BK20: 4.5499117e+11 | BL20: 4.4459616e+11 | BM20: 4.3504932e+11 | BN20: 4.7929536e+11 | BO20: 4.7094193e+11 | BP20: 5.1603414e+11
A21: Azerbaijan | B21: AZE | C21: GDP (current US$) | D21: NY.GDP.MKTP.CD | AI21: 8.8848485e+09 | AJ21: 5344000000 | AK21: 4.4465867e+08 | AL21: 1.5703926e+09 | AM21: 1.1931411e+09 | AN21: 2.4173312e+09 | AO21: 3.1765074e+09 | AP21: 3.9623624e+09 | AQ21: 4.4463686e+09 | AR21: 4.5812486e+09 | AS21: 5.2726157e+09 | AT21: 5.7076162e+09 | AU21: 6.2360877e+09 | AV21: 7.2764131e+09 | AW21: 8.6804057e+09 | AX21: 1.3245422e+10 | AY21: 2.0981929e+10 | AZ21: 3.3049419e+10 | BA21: 4.8851294e+10 | BB21: 4.4292427e+10 | BC21: 5.2909295e+10 | BD21: 6.5952796e+10 | BE21: 6.9679945e+10 | BF21: 7.416056e+10 | BG21: 7.5239785e+10 | BH21: 5.3076235e+10 | BI21: 3.7866997e+10 | BJ21: 4.0866627e+10 | BK21: 4.711247e+10 | BL21: 4.8174235e+10 | BM21: 42693000000 | BN21: 5.4825412e+10 | BO21: 7.8807471e+10 | BP21: 7.2356176e+10
A22: Burundi | B22: BDI | C22: GDP (current US$) | D22: NY.GDP.MKTP.CD | E22: 195999990 | F22: 202999992 | G22: 213500006 | H22: 232749998 | I22: 260750008 | J22: 1.5899496e+08 | K22: 1.6544457e+08 | L22: 1.7829714e+08 | M22: 183200000 | N22: 1.9020571e+08 | O22: 2.4273257e+08 | P22: 2.5284229e+08 | Q22: 2.4680457e+08 | R22: 3.0433984e+08 | S22: 3.4526349e+08 | T22: 4.2098667e+08 | U22: 4.4841275e+08 | V22: 5.4753556e+08 | W22: 6.1022556e+08 | X22: 7.8249667e+08 | Y22: 9.1972667e+08 | Z22: 9.6904667e+08 | AA22: 1.0132222e+09 | AB22: 1.0829263e+09 | AC22: 9.8714393e+08 | AD22: 1.1499793e+09 | AE22: 1.2017255e+09 | AF22: 1.1314665e+09 | AG22: 1.0824032e+09 | AH22: 1.1139241e+09 | AI22: 1.1321013e+09 | AJ22: 1.1673985e+09 | AK22: 1.0830377e+09 | AL22: 9.3863261e+08 | AM22: 9.2503059e+08 | AN22: 1.0004284e+09 | AO22: 8.6903386e+08 | AP22: 9.7289627e+08 | AQ22: 8.9377074e+08 | AR22: 8.0807722e+08 | AS22: 8.7048607e+08 | AT22: 8.7679472e+08 | AU22: 8.2539452e+08 | AV22: 7.8465442e+08 | AW22: 9.1525732e+08 | AX22: 1.1171131e+09 | AY22: 1.2733751e+09 | AZ22: 1.3561994e+09 | BA22: 1.6118359e+09 | BB22: 1.7814551e+09 | BC22: 2.0321352e+09 | BD22: 2.2358208e+09 | BE22: 2.3333413e+09 | BF22: 2.4516066e+09 | BG22: 2.7057833e+09 | BH22: 3.1040035e+09 | BI22: 2.6444878e+09 | BJ22: 2.723587e+09 | BK22: 2.6671822e+09 | BL22: 2.5765189e+09 | BM22: 2.6496803e+09 | BN22: 2.7757987e+09 | BO22: 3.3387228e+09 | BP22: 2.6421617e+09
A23: Belgium | B23: BEL | C23: GDP (current US$) | D23: NY.GDP.MKTP.CD | E23: 1.1810619e+10 | F23: 1.2561702e+10 | G23: 1.3436827e+10 | H23: 1.4445805e+10 | I23: 1.6168044e+10 | J23: 1.7597783e+10 | K23: 1.8894891e+10 | L23: 2.0252509e+10 | M23: 2.1654857e+10 | N23: 2.4019653e+10 | O23: 2.6706196e+10 | P23: 2.9821662e+10 | Q23: 3.7209418e+10 | R23: 4.7743801e+10 | S23: 5.6033078e+10 | T23: 6.5678189e+10 | U23: 7.1113883e+10 | V23: 8.2839905e+10 | W23: 1.0124653e+11 | X23: 1.1631546e+11 | Y23: 1.2682931e+11 | Z23: 1.0473002e+11 | AA23: 9.2095926e+10 | AB23: 8.7184239e+10 | AC23: 8.334953e+10 | AD23: 8.6268264e+10 | AE23: 1.2001879e+11 | AF23: 1.493944e+11 | AG23: 1.622991e+11 | AH23: 1.6422106e+11 | AI23: 2.0533175e+11 | AJ23: 2.10511e+11 | AK23: 2.3478165e+11 | AL23: 2.247218e+11 | AM23: 2.4488413e+11 | AN23: 2.8802559e+11 | AO23: 2.7920143e+11 | AP23: 2.5270805e+11 | AQ23: 2.5852834e+11 | AR23: 2.5824573e+11 | AS23: 2.3679246e+11 | AT23: 2.3674614e+11 | AU23: 2.583836e+11 | AV23: 3.1808253e+11 | AW23: 3.6921471e+11 | AX23: 3.8571476e+11 | AY23: 4.0825984e+11 | AZ23: 4.7092216e+11 | BA23: 5.1732809e+11 | BB23: 4.8325417e+11 | BC23: 4.8142088e+11 | BD23: 5.2333035e+11 | BE23: 4.9615288e+11 | BF23: 5.2179102e+11 | BG23: 5.353902e+11 | BH23: 4.6233557e+11 | BI23: 4.7606276e+11 | BJ23: 5.0276472e+11 | BK23: 5.4329907e+11 | BL23: 5.358658e+11 | BM23: 5.2602151e+11 | BN23: 6.0090446e+11 | BO23: 5.8361398e+11 | BP23: 6.3221658e+11
A24: Benin | B24: BEN | C24: GDP (current US$) | D24: NY.GDP.MKTP.CD | E24: 2.2619558e+08 | F24: 2.3566822e+08 | G24: 2.3643495e+08 | H24: 2.539277e+08 | I24: 2.6981901e+08 | J24: 2.8990868e+08 | K24: 3.0292524e+08 | L24: 3.0622195e+08 | M24: 3.2632311e+08 | N24: 3.3074824e+08 | O24: 3.3362771e+08 | P24: 3.3507303e+08 | Q24: 4.1033186e+08 | R24: 5.0437607e+08 | S24: 5.5465486e+08 | T24: 6.7687014e+08 | U24: 6.9840826e+08 | V24: 7.5004978e+08 | W24: 9.2884347e+08 | X24: 1.186231e+09 | Y24: 1.4052518e+09 | Z24: 1.2911202e+09 | AA24: 1.2677787e+09 | AB24: 1.0953482e+09 | AC24: 1.051134e+09 | AD24: 1.0457128e+09 | AE24: 1.336102e+09 | AF24: 1.5624122e+09 | AG24: 1.6202461e+09 | AH24: 1.5022944e+09 | AI24: 1.9599653e+09 | AJ24: 1.9864378e+09 | AK24: 1.6953153e+09 | AL24: 2.2745581e+09 | AM24: 1.5980759e+09 | AN24: 2.1696271e+09 | AO24: 2.3611164e+09 | AP24: 2.2683016e+09 | AQ24: 2.4550927e+09 | AR24: 3.677394e+09 | AS24: 3.5199914e+09 | AT24: 3.6662226e+09 | AU24: 4.1943427e+09 | AV24: 5.3492581e+09 | AW24: 6.1902704e+09 | AX24: 6.567655e+09 | AY24: 7.0341113e+09 | AZ24: 8.1690484e+09 | BA24: 9.7877345e+09 | BB24: 9.7386265e+09 | BC24: 9.535345e+09 | BD24: 1.0693321e+10 | BE24: 1.1141358e+10 | BF24: 1.2517845e+10 | BG24: 1.3284528e+10 | BH24: 1.1388161e+10 | BI24: 1.1821066e+10 | BJ24: 1.2701656e+10 | BK24: 1.4262408e+10 | BL24: 1.4390709e+10 | BM24: 1.5686742e+10 | BN24: 1.7687624e+10 | BO24: 1.7425418e+10 | BP24: 1.9673285e+10
A25: Burkina Faso | B25: BFA | C25: GDP (current US$) | D25: NY.GDP.MKTP.CD | E25: 3.3044282e+08 | F25: 3.5024723e+08 | G25: 3.795671e+08 | H25: 3.9404067e+08 | I25: 4.1032164e+08 | J25: 4.2291679e+08 | K25: 4.3388977e+08 | L25: 4.5075392e+08 | M25: 4.6044269e+08 | N25: 4.7829865e+08 | O25: 4.5840427e+08 | P25: 4.8241118e+08 | Q25: 5.7859552e+08 | R25: 6.7477357e+08 | S25: 7.5113343e+08 | T25: 9.399727e+08 | U25: 9.7654719e+08 | V25: 1.1312249e+09 | W25: 1.4755836e+09 | X25: 1.7484806e+09 | Y25: 1.9287199e+09 | Z25: 1.7758423e+09 | AA25: 1.7544501e+09 | AB25: 1.6002786e+09 | AC25: 1.4598801e+09 | AD25: 1.5524932e+09 | AE25: 2.0363034e+09 | AF25: 2.3698349e+09 | AG25: 2.6160405e+09 | AH25: 2.6155877e+09 | AI25: 3.1013008e+09 | AJ25: 3.1350456e+09 | AK25: 3.3566925e+09 | AL25: 3.1995365e+09 | AM25: 1.8952906e+09 | AN25: 2.379518e+09 | AO25: 2.5865506e+09 | AP25: 2.4476691e+09 | AQ25: 2.8049024e+09 | AR25: 3.3895667e+09 | AS25: 2.9683701e+09 | AT25: 3.1903711e+09 | AU25: 3.6223501e+09 | AV25: 4.7407681e+09 | AW25: 5.4516885e+09 | AX25: 6.1463532e+09 | AY25: 6.5474198e+09 | AZ25: 7.6257228e+09 | BA25: 9.4514355e+09 | BB25: 9.4506969e+09 | BC25: 1.010962e+10 | BD25: 1.2080296e+10 | BE25: 1.2561015e+10 | BF25: 1.34443e+10 | BG25: 1.3943016e+10 | BH25: 1.1832159e+10 | BI25: 1.2833363e+10 | BJ25: 1.4106956e+10 | BK25: 1.5890066e+10 | BL25: 1.6032814e+10 | BM25: 1.7725011e+10 | BN25: 1.9643167e+10 | BO25: 1.8820219e+10 | BP25: 2.0324618e+10
A26: Bangladesh | B26: BGD | C26: GDP (current US$) | D26: NY.GDP.MKTP.CD | E26: 4.2748941e+09 | F26: 4817580375 | G26: 5.0814135e+09 | H26: 5.3194586e+09 | I26: 5.3860548e+09 | J26: 5.9066368e+09 | K26: 6.4396879e+09 | L26: 7.2535757e+09 | M26: 7.4836858e+09 | N26: 8.4710064e+09 | O26: 8.9927222e+09 | P26: 8.7518432e+09 | Q26: 6.2882459e+09 | R26: 8.0867257e+09 | S26: 1.2512461e+10 | T26: 1.9448348e+10 | U26: 1.0117113e+10 | V26: 9.6511493e+09 | W26: 1.3281767e+10 | X26: 1.556548e+10 | Y26: 1.8138049e+10 | Z26: 2.0249694e+10 | AA26: 1.8525399e+10 | AB26: 1.7609049e+10 | AC26: 18920840000 | AD26: 2.2278423e+10 | AE26: 2.1774033e+10 | AF26: 2.4298032e+10 | AG26: 2.6579006e+10 | AH26: 2.8781715e+10 | AI26: 3.1598341e+10 | AJ26: 3.0957484e+10 | AK26: 3.1708875e+10 | AL26: 3.3166519e+10 | AM26: 3.3768661e+10 | AN26: 3.7939749e+10 | AO26: 4.6438484e+10 | AP26: 4.8244309e+10 | AQ26: 4.9984559e+10 | AR26: 5.127057e+10 | AS26: 5.3369787e+10 | AT26: 5.399129e+10 | AU26: 5.4724081e+10 | AV26: 6.0158929e+10 | AW26: 6.5108544e+10 | AX26: 6.9476001e+10 | AY26: 7.1795736e+10 | AZ26: 7.9611645e+10 | BA26: 9.1636997e+10 | BB26: 1.0247516e+11 | BC26: 1.1527554e+11 | BD26: 1.2860748e+11 | BE26: 1.3331075e+11 | BF26: 1.4999896e+11 | BG26: 1.7288661e+11 | BH26: 1.9514661e+11 | BI26: 2.6522451e+11 | BJ26: 2.9373245e+11 | BK26: 3.2136275e+11 | BL26: 3.5123166e+11 | BM26: 3.7397944e+11 | BN26: 4.1627165e+11 | BO26: 4.6013169e+11 | BP26: 4.3741533e+11
A27: Bulgaria | B27: BGR | C27: GDP (current US$) | D27: NY.GDP.MKTP.CD | Y27: 1.9839231e+10 | Z27: 19870000000 | AA27: 19342000000 | AB27: 1.6563667e+10 | AC27: 1.7594944e+10 | AD27: 1.7155421e+10 | AE27: 2.0249294e+10 | AF27: 28101000000 | AG27: 2.2555941e+10 | AH27: 2.1988444e+10 | AI27: 2.0632091e+10 | AJ27: 1.0943548e+10 | AK27: 1.0350515e+10 | AL27: 1.0832065e+10 | AM27: 9.697417e+09 | AN27: 1.8991484e+10 | AO27: 1.2294965e+10 | AP27: 1.1316127e+10 | AQ27: 1.5031055e+10 | AR27: 1.3627325e+10 | AS27: 1.324599e+10 | AT27: 1.4183446e+10 | AU27: 1.6403044e+10 | AV27: 2.1144958e+10 | AW27: 2.6157743e+10 | AX27: 2.9868658e+10 | AY27: 3.4380536e+10 | AZ27: 4.4432812e+10 | BA27: 5.4480684e+10 | BB27: 5.2023801e+10 | BC27: 5.0760929e+10 | BD27: 5.7737041e+10 | BE27: 5.4288135e+10 | BF27: 5.5852124e+10 | BG27: 5.7157783e+10 | BH27: 5.0811996e+10 | BI27: 5.3964253e+10 | BJ27: 5.9309748e+10 | BK27: 6.6370132e+10 | BL27: 6.888101e+10 | BM27: 7.0368758e+10 | BN27: 8.4041493e+10 | BO27: 9.034617e+10 | BP27: 1.0158438e+11
A28: Bahrain | B28: BHR | C28: GDP (current US$) | D28: NY.GDP.MKTP.CD | O28: 3.9157736e+08 | P28: 4.2218156e+08 | Q28: 5.3408118e+08 | R28: 7.6113254e+08 | S28: 1.0421769e+09 | T28: 1.0991076e+09 | U28: 1.5817095e+09 | V28: 1.9890603e+09 | W28: 2.272043e+09 | X28: 2.7101607e+09 | Y28: 3.4938345e+09 | Z28: 3.9431095e+09 | AA28: 4.1454211e+09 | AB28: 4.2470305e+09 | AC28: 4.4408746e+09 | AD28: 4.1523765e+09 | AE28: 3.4707468e+09 | AF28: 3.8569227e+09 | AG28: 4.2098342e+09 | AH28: 4.393094e+09 | AI28: 4.809511e+09 | AJ28: 5.2489112e+09 | AK28: 5.4022324e+09 | AL28: 5.9130011e+09 | AM28: 6.3306279e+09 | AN28: 6.6511809e+09 | AO28: 6.9381668e+09 | AP28: 7.2194077e+09 | AQ28: 7.031309e+09 | AR28: 7.5284691e+09 | AS28: 9.0628989e+09 | AT28: 8.9761968e+09 | AU28: 9.5935106e+09 | AV28: 1.1074814e+10 | AW28: 1.315016e+10 | AX28: 1.5968723e+10 | AY28: 1.8504761e+10 | AZ28: 21730000000 | BA28: 2.5710904e+10 | BB28: 2.2938218e+10 | BC28: 2.5713271e+10 | BD28: 2.8776596e+10 | BE28: 3.0749309e+10 | BF28: 3.2539468e+10 | BG28: 3.3387713e+10 | BH28: 3.1125851e+10 | BI28: 3.2250133e+10 | BJ28: 3.5423644e+10 | BK28: 3.7802005e+10 | BL28: 3.8653318e+10 | BM28: 3.4621808e+10 | BN28: 3.928867e+10 | BO28: 4.4383298e+10 | BP28: 43205000000
A29: Bahamas, The | B29: BHS | C29: GDP (current US$) | D29: NY.GDP.MKTP.CD | E29: 1.6980392e+08 | F29: 1.9009804e+08 | G29: 2.122549e+08 | H29: 2.377451e+08 | I29: 2.6666667e+08 | J29: 3.0039216e+08 | K29: 340000000 | L29: 3.9019608e+08 | M29: 4.4490196e+08 | N29: 5.2813725e+08 | O29: 5.3842315e+08 | P29: 573400000 | Q29: 590900000 | R29: 670900000 | S29: 632400000 | T29: 596200000 | U29: 642100000 | V29: 713000000 | W29: 832400000 | X29: 1139800100 | Y29: 1335300000 | Z29: 1426500000 | AA29: 1578300000 | AB29: 1732800000 | AC29: 2041100000 | AD29: 2320699900 | AE29: 2472500000 | AF29: 2713999900 | AG29: 2817900000 | AH29: 3062000000 | AI29: 3166000000 | AJ29: 3111160000 | AK29: 3109000000 | AL29: 3092000000 | AM29: 3259000000 | AN29: 3429000000 | AO29: 3609000000 | AP29: 6332360000 | AQ29: 6833220000 | AR29: 7683870000 | AS29: 8076470000 | AT29: 8317830000 | AU29: 8881160000 | AV29: 8870090000 | AW29: 9055290000 | AX29: 9836200000 | AY29: 10167250000 | AZ29: 10618340000 | BA29: 10526000000 | BB29: 9981960000 | BC29: 10095760000 | BD29: 10070450000 | BE29: 10720500000 | BF29: 10395800000 | BG29: 10974100000 | BH29: 11671900000 | BI29: 11745100000 | BJ29: 12236700000 | BK29: 12615800000 | BL29: 13016200000 | BM29: 9958200000 | BN29: 11368900000 | BO29: 13136400000 | BP29: 14338500000
A30: Bosnia and Herzegovina | B30: BIH | C30: GDP (current US$) | D30: NY.GDP.MKTP.CD | AI30: 7.7534783e+09 | AJ30: 6.1229592e+09 | AK30: 4.7350447e+09 | AL30: 3.6306689e+09 | AM30: 1.2558025e+09 | AN30: 1.866573e+09 | AO30: 2.7860453e+09 | AP30: 3.6719097e+09 | AQ30: 4.1167743e+09 | AR30: 4.6862564e+09 | AS30: 5.5677728e+09 | AT30: 5.8006155e+09 | AU30: 6.7282209e+09 | AV30: 8.4988944e+09 | AW30: 1.0156542e+10 | AX30: 1.1222796e+10 | AY30: 1.2864842e+10 | AZ30: 1.5778734e+10 | BA30: 1.9112797e+10 | BB30: 1.7613949e+10 | BC30: 1.7176316e+10 | BD30: 1.8644234e+10 | BE30: 1.7226736e+10 | BF30: 1.8179109e+10 | BG30: 1.8558734e+10 | BH30: 1.6404349e+10 | BI30: 1.7116926e+10 | BJ30: 1.8326373e+10 | BK30: 2.0484054e+10 | BL30: 2.0482609e+10 | BM30: 2.0226037e+10 | BN30: 2.3672712e+10 | BO30: 2.4534664e+10 | BP30: 2.7054889e+10
A31: Belarus | B31: BLR | C31: GDP (current US$) | D31: NY.GDP.MKTP.CD | AK31: 9200000000 | AL31: 1.6416667e+10 | AM31: 1.4952101e+10 | AN31: 1.3970426e+10 | AO31: 1.4756846e+10 | AP31: 1.4130586e+10 | AQ31: 1.5221353e+10 | AR31: 1.2138243e+10 | AS31: 1.273678e+10 | AT31: 1.235482e+10 | AU31: 1.4594901e+10 | AV31: 1.7825445e+10 | AW31: 2.3141566e+10 | AX31: 3.0210092e+10 | AY31: 3.6961894e+10 | AZ31: 4.5275712e+10 | BA31: 6.0752106e+10 | BB31: 5.0873167e+10 | BC31: 5.7231905e+10 | BD31: 6.1762382e+10 | BE31: 6.568589e+10 | BF31: 7.5527559e+10 | BG31: 7.8812805e+10 | BH31: 5.6454889e+10 | BI31: 4.7723545e+10 | BJ31: 5.4725302e+10 | BK31: 6.0031174e+10 | BL31: 6.4410123e+10 | BM31: 6.1371755e+10 | BN31: 6.9673747e+10 | BO31: 7.377518e+10 | BP31: 7.1857383e+10
A32: Belize | B32: BLZ | C32: GDP (current US$) | D32: NY.GDP.MKTP.CD | E32: 28072478 | F32: 29965000 | G32: 31857592 | H32: 33750114 | I32: 36194586 | J32: 40110040 | K32: 44450044 | L32: 47431256 | M32: 44999910 | N32: 47399905 | O32: 53339893 | P32: 59074687 | Q32: 65998069 | R32: 78214768 | S32: 1.0316045e+08 | T32: 1.1819403e+08 | U32: 97094227 | V32: 117650000 | W32: 136300000 | X32: 151800000 | Y32: 1.9793822e+08 | Z32: 1.9608985e+08 | AA32: 1.8220633e+08 | AB32: 1.9210319e+08 | AC32: 2.1438195e+08 | AD32: 2.1264374e+08 | AE32: 2.3163832e+08 | AF32: 2.8108256e+08 | AG32: 3.2009336e+08 | AH32: 3.6913389e+08 | AI32: 5.4568637e+08 | AJ32: 5.949757e+08 | AK32: 6.9362517e+08 | AL32: 7.5001877e+08 | AM32: 7.6964951e+08 | AN32: 8.1649162e+08 | AO32: 8.4820528e+08 | AP32: 8.7086112e+08 | AQ32: 9.2655076e+08 | AR32: 9.9690647e+08 | AS32: 1.1347568e+09 | AT32: 1.168128e+09 | AU32: 1.2400595e+09 | AV32: 1.3033819e+09 | AW32: 1.394274e+09 | AX32: 1.468146e+09 | AY32: 1.5842074e+09 | AZ32: 1.6992143e+09 | BA32: 1.7319216e+09 | BB32: 1.6814733e+09 | BC32: 1.7390703e+09 | BD32: 1.8188319e+09 | BE32: 1.8995032e+09 | BF32: 2.0217574e+09 | BG32: 2.1251256e+09 | BH32: 2.1947093e+09 | BI32: 2.2405935e+09 | BJ32: 2.2666648e+09 | BK32: 2.2927873e+09 | BL32: 2.3867925e+09 | BM32: 2.0477278e+09 | BN32: 2.4245752e+09 | BO32: 2.8305076e+09 | BP32: 3281500000
A33: Bermuda | B33: BMU | C33: GDP (current US$) | D33: NY.GDP.MKTP.CD | E33: 84466653 | F33: 89249985 | G33: 94149984 | H33: 96366651 | I33: 1.0756665e+08 | J33: 1.1433905e+08 | K33: 1.3417338e+08 | L33: 1.5510298e+08 | M33: 150000000 | N33: 164900000 | O33: 186300000 | P33: 211100000 | Q33: 235400000 | R33: 269500000 | S33: 312600000 | T33: 345000000 | U33: 386300000 | V33: 447000000 | W33: 475800000 | X33: 517200000 | Y33: 613299968 | Z33: 739100032 | AA33: 785500032 | AB33: 889400000 | AC33: 985699968 | AD33: 1039500032 | AE33: 1173500032 | AF33: 1296499968 | AG33: 1415100032 | AH33: 1501500032 | AI33: 1592400000 | AJ33: 1634900000 | AK33: 1679900000 | AL33: 1820359900 | AM33: 1867160100 | AN33: 2030750000 | AO33: 2695390000 | AP33: 2932827000 | AQ33: 3130748000 | AR33: 3324433000 | AS33: 3480219000 | AT33: 3680483000 | AU33: 3937228000 | AV33: 4186525000 | AW33: 4484703000 | AX33: 4868136000 | AY33: 6144000000 | AZ33: 6767000000 | BA33: 6980000000 | BB33: 6656000000 | BC33: 6634526000 | BD33: 6312691000 | BE33: 6378188000 | BF33: 6465756000 | BG33: 6413988000 | BH33: 6654541000 | BI33: 6899911000 | BJ33: 7142316000 | BK33: 7225977000 | BL33: 7423465000 | BM33: 6887147000 | BN33: 7286607000 | BO33: 7827980000
A34: Bolivia | B34: BOL | C34: GDP (current US$) | D34: NY.GDP.MKTP.CD | E34: 373250000 | F34: 406000000 | G34: 4.4391667e+08 | H34: 478000000 | I34: 5.3858333e+08 | J34: 5.9833333e+08 | K34: 662500000 | L34: 748250000 | M34: 8.4933333e+08 | N34: 9.2033333e+08 | O34: 1.0068333e+09 | P34: 1.0846667e+09 | Q34: 1.2861538e+09 | R34: 1263600000 | S34: 2101300000 | T34: 2405900000 | U34: 2733350000 | V34: 3229050000 | W34: 3760100000 | X34: 4510500000 | Y34: 4.450368e+09 | Z34: 5.7784878e+09 | AA34: 5.6003856e+09 | AB34: 5.4140081e+09 | AC34: 6.1693045e+09 | AD34: 5.3772767e+09 | AE34: 3.9593835e+09 | AF34: 4.3479563e+09 | AG34: 4.5976117e+09 | AH34: 4.7159734e+09 | AI34: 4.8675826e+09 | AJ34: 5.3432625e+09 | AK34: 5.6438687e+09 | AL34: 5.7346995e+09 | AM34: 5.9812229e+09 | AN34: 6.7151617e+09 | AO34: 7.3969491e+09 | AP34: 7.9257368e+09 | AQ34: 8.4974947e+09 | AR34: 8.2850644e+09 | AS34: 8.3978555e+09 | AT34: 8.1415169e+09 | AU34: 7.9054851e+09 | AV34: 8.0823996e+09 | AW34: 8.7734518e+09 | AX34: 9.5491229e+09 | AY34: 1.1451845e+10 | AZ34: 1.3120108e+10 | BA34: 1.6674276e+10 | BB34: 1.7339992e+10 | BC34: 1.9649724e+10 | BD34: 2.3963165e+10 | BE34: 2.7084497e+10 | BF34: 3.0659339e+10 | BG34: 3.2996188e+10 | BH34: 3.3000198e+10 | BI34: 3.3941126e+10 | BJ34: 3.7508642e+10 | BK34: 4.0287648e+10 | BL34: 4.0895323e+10 | BM34: 3.6629844e+10 | BN34: 4.0406112e+10 | BO34: 4.4008283e+10 | BP34: 4.5849833e+10
A35: Brazil | B35: BRA | C35: GDP (current US$) | D35: NY.GDP.MKTP.CD | AH35: 4.2559531e+11 | AI35: 3.8495982e+11 | AJ35: 3.4253409e+11 | AK35: 3.2819191e+11 | AL35: 3.6829203e+11 | AM35: 5.2536947e+11 | AN35: 7.6933305e+11 | AO35: 8.5042643e+11 | AP35: 8.8320618e+11 | AQ35: 8.6371076e+11 | AR35: 5.9964202e+11 | AS35: 6.5544823e+11 | AT35: 5.5998363e+11 | AU35: 5.0979527e+11 | AV35: 5.5823375e+11 | AW35: 6.6928942e+11 | AX35: 8.9163384e+11 | AY35: 1.1076265e+12 | AZ35: 1.3971145e+12 | BA35: 1.6958551e+12 | BB35: 1.6669964e+12 | BC35: 2.2088377e+12 | BD35: 2.6161562e+12 | BE35: 2.4652278e+12 | BF35: 2.4728195e+12 | BG35: 2.4560437e+12 | BH35: 1.8022122e+12 | BI35: 1.7956935e+12 | BJ35: 2.063515e+12 | BK35: 1.9169339e+12 | BL35: 1.8732882e+12 | BM35: 1.4761072e+12 | BN35: 1.6706474e+12 | BO35: 1.9519239e+12 | BP35: 2.1736657e+12
A36: Barbados | B36: BRB | C36: GDP (current US$) | D36: NY.GDP.MKTP.CD | E36: 80021380 | F36: 85363261 | G36: 88782065 | H36: 99893178 | I36: 99252153 | J36: 1.0502138e+08 | K36: 1.1319446e+08 | L36: 1.2555394e+08 | M36: 1.2573367e+08 | N36: 1.4139314e+08 | O36: 1.662102e+08 | P36: 1.8682423e+08 | Q36: 2.137231e+08 | R36: 2.6077062e+08 | S36: 3.1180934e+08 | T36: 4.0217861e+08 | U36: 4.3591127e+08 | V36: 4.9509767e+08 | W36: 5.5288371e+08 | X36: 6.7036245e+08 | Y36: 1.0122806e+09 | Z36: 1.1142047e+09 | AA36: 1.1639238e+09 | AB36: 1.2360165e+09 | AC36: 1.3468901e+09 | AD36: 1.4095361e+09 | AE36: 1.5477552e+09 | AF36: 1.7043703e+09 | AG36: 1.8127579e+09 | AH36: 2.0061652e+09 | AI36: 2.0121315e+09 | AJ36: 2.0205837e+09 | AK36: 1957000000 | AL36: 2.0633421e+09 | AM36: 2.1513449e+09 | AN36: 2.2169741e+09 | AO36: 2.3636454e+09 | AP36: 2.4983841e+09 | AQ36: 2.8170835e+09 | AR36: 2.9518222e+09 | AS36: 3059500000 | AT36: 3054500000 | AU36: 3106500000 | AV36: 3209500000 | AW36: 3444500000 | AX36: 3819500000 | AY36: 4217323400 | AZ36: 4675767950 | BA36: 4790410400 | BB36: 4466809600 | BC36: 4534772750 | BD36: 4662343500 | BE36: 4622687600 | BF36: 4693452700 | BG36: 4711838650 | BH36: 4738650450 | BI36: 4848210350 | BJ36: 5000457800 | BK36: 5128345200 | BL36: 5367139250 | BM36: 4779756550 | BN36: 4945276000 | BO36: 5840673700 | BP36: 6.3935642e+09
A37: Brunei Darussalam | B37: BRN | C37: GDP (current US$) | D37: NY.GDP.MKTP.CD | J37: 1.140395e+08 | K37: 1.3275753e+08 | L37: 1.3902954e+08 | M37: 1.6081824e+08 | N37: 1.6121024e+08 | O37: 1.7907893e+08 | P37: 1.9752577e+08 | Q37: 2.7082278e+08 | R37: 4.3309553e+08 | S37: 1.0735916e+09 | T37: 1.1683043e+09 | U37: 1.4230372e+09 | V37: 1.7327212e+09 | W37: 1.9415794e+09 | X37: 2.8038342e+09 | Y37: 4.9288065e+09 | Z37: 4.3662304e+09 | AA37: 4.2642025e+09 | AB37: 3.8446322e+09 | AC37: 3.7825532e+09 | AD37: 3.5235325e+09 | AE37: 2.3585744e+09 | AF37: 2.7544857e+09 | AG37: 2.6906841e+09 | AH37: 2.9855323e+09 | AI37: 3.5204876e+09 | AJ37: 3.7017742e+09 | AK37: 4.1836329e+09 | AL37: 4.105729e+09 | AM37: 4.0872202e+09 | AN37: 4.7341035e+09 | AO37: 5.1154541e+09 | AP37: 5.197312e+09 | AQ37: 4.0511424e+09 | AR37: 4.6001167e+09 | AS37: 6.0012821e+09 | AT37: 5.6010187e+09 | AU37: 5.8433683e+09 | AV37: 6.5573971e+09 | AW37: 7.8722028e+09 | AX37: 9.53142e+09 | AY37: 1.1470465e+10 | AZ37: 1.2247678e+10 | BA37: 1.4393434e+10 | BB37: 1.0732595e+10 | BC37: 1.370728e+10 | BD37: 1.8525129e+10 | BE37: 1.9048443e+10 | BF37: 1.8094322e+10 | BG37: 1.7097803e+10 | BH37: 1.2930291e+10 | BI37: 1.1400466e+10 | BJ37: 1.2128184e+10 | BK37: 1.3566938e+10 | BL37: 1.3469235e+10 | BM37: 1.20058e+10 | BN37: 1.4006497e+10 | BO37: 1.6681536e+10 | BP37: 1.5128293e+10
A38: Bhutan | B38: BTN | C38: GDP (current US$) | D38: NY.GDP.MKTP.CD | O38: 61812113 | P38: 66289450 | Q38: 70139867 | R38: 78900289 | S38: 92901785 | T38: 86820762 | U38: 88461263 | V38: 97884434 | W38: 94086228 | X38: 1.05378e+08 | Y38: 1.286692e+08 | Z38: 1.3917418e+08 | AA38: 1.4143932e+08 | AB38: 1.5670429e+08 | AC38: 1.6042349e+08 | AD38: 1.6328882e+08 | AE38: 1.9121812e+08 | AF38: 2.4274277e+08 | AG38: 2.7229807e+08 | AH38: 2.6479863e+08 | AI38: 2.8776501e+08 | AJ38: 2.4029429e+08 | AK38: 2.4023353e+08 | AL38: 2.2597369e+08 | AM38: 2.5895471e+08 | AN38: 2.9049098e+08 | AO38: 3.0340835e+08 | AP38: 3.5222908e+08 | AQ38: 3.6345838e+08 | AR38: 3.993112e+08 | AS38: 4.6073342e+08 | AT38: 4.9611023e+08 | AU38: 5.5934526e+08 | AV38: 6.5193543e+08 | AW38: 7.3534849e+08 | AX38: 8.60391e+08 | AY38: 9.4287988e+08 | AZ38: 1.255768e+09 | BA38: 1.3175178e+09 | BB38: 1.3313438e+09 | BC38: 1.6734643e+09 | BD38: 1.9384413e+09 | BE38: 1.9397307e+09 | BF38: 1.9131625e+09 | BG38: 2.0573309e+09 | BH38: 2.154921e+09 | BI38: 2.3227305e+09 | BJ38: 2.5913581e+09 | BK38: 2.5833357e+09 | BL38: 2.7356834e+09 | BM38: 2.457604e+09 | BN38: 2.7688028e+09 | BO38: 2.8982277e+09
A39: Botswana | B39: BWA | C39: GDP (current US$) | D39: NY.GDP.MKTP.CD | E39: 30411414 | F39: 32902613 | G39: 35644957 | H39: 38091843 | I39: 41616348 | J39: 45788696 | K39: 51465655 | L39: 58642354 | M39: 66248441 | N39: 77361547 | O39: 96243234 | P39: 1.2744861e+08 | Q39: 1.6446091e+08 | R39: 2.4412416e+08 | S39: 3.0604421e+08 | T39: 3.5516857e+08 | U39: 3.7202509e+08 | V39: 4.5162478e+08 | W39: 5.9040737e+08 | X39: 8.1987026e+08 | Y39: 1.0608897e+09 | Z39: 1.0738128e+09 | AA39: 1.0149457e+09 | AB39: 1.1722304e+09 | AC39: 1.2408222e+09 | AD39: 1.1147833e+09 | AE39: 1.3926022e+09 | AF39: 1.9652269e+09 | AG39: 2.6445542e+09 | AH39: 3.0838221e+09 | AI39: 3.7906363e+09 | AJ39: 3.9428767e+09 | AK39: 4.1464646e+09 | AL39: 4.1601292e+09 | AM39: 4.2592596e+09 | AN39: 4.7305991e+09 | AO39: 4.8477572e+09 | AP39: 5.0202656e+09 | AQ39: 4.7904815e+09 | AR39: 5.4842633e+09 | AS39: 5.7883296e+09 | AT39: 5.4896083e+09 | AU39: 5.438864e+09 | AV39: 7.5115822e+09 | AW39: 8.9574677e+09 | AX39: 9.9189071e+09 | AY39: 9.9191585e+09 | AZ39: 1.0567271e+10 | BA39: 1.0730829e+10 | BB39: 1.0118459e+10 | BC39: 1.2637273e+10 | BD39: 1.5110644e+10 | BE39: 1.3907465e+10 | BF39: 1.4271739e+10 | BG39: 1.5470089e+10 | BH39: 1.3530749e+10 | BI39: 1.5082637e+10 | BJ39: 1.6105156e+10 | BK39: 1.7031943e+10 | BL39: 1.6725908e+10 | BM39: 1.4960291e+10 | BN39: 1.8750947e+10 | BO39: 2.0321959e+10 | BP39: 1.9395765e+10
A40: Central African Republic | B40: CAF | C40: GDP (current US$) | D40: NY.GDP.MKTP.CD | E40: 1.121556e+08 | F40: 1.2313458e+08 | G40: 1.2448277e+08 | H40: 1.2937912e+08 | I40: 1.4202508e+08 | J40: 1.505748e+08 | K40: 1.5793002e+08 | L40: 1.6382051e+08 | M40: 1.9176744e+08 | N40: 1.8803921e+08 | O40: 1.8910653e+08 | P40: 2.014508e+08 | Q40: 2.3031788e+08 | R40: 2.7118308e+08 | S40: 2.8139871e+08 | T40: 3.7866002e+08 | U40: 4.5115246e+08 | V40: 5.0729815e+08 | W40: 6.1057863e+08 | X40: 7.0076475e+08 | Y40: 7.970482e+08 | Z40: 6.9480362e+08 | AA40: 7.4831239e+08 | AB40: 6.5867933e+08 | AC40: 6.3782067e+08 | AD40: 8.6484984e+08 | AE40: 1.122265e+09 | AF40: 1.200992e+09 | AG40: 1.2648993e+09 | AH40: 1.2339303e+09 | AI40: 1.4407115e+09 | AJ40: 1.377375e+09 | AK40: 1.4119176e+09 | AL40: 1.2787813e+09 | AM40: 8.5117436e+08 | AN40: 1.1153897e+09 | AO40: 1.0077911e+09 | AP40: 9.3774151e+08 | AQ40: 9.6733839e+08 | AR40: 9.9947751e+08 | AS40: 9.1677728e+08 | AT40: 9.326486e+08 | AU40: 9.9606814e+08 | AV40: 1.1423155e+09 | AW40: 1.2723605e+09 | AX40: 1.3378944e+09 | AY40: 1.4618598e+09 | AZ40: 1.6998113e+09 | BA40: 1.9934079e+09 | BB40: 2.0673817e+09 | BC40: 2.1425915e+09 | BD40: 2.4379827e+09 | BE40: 2.5101265e+09 | BF40: 1.6915441e+09 | BG40: 1.8948134e+09 | BH40: 1.6958257e+09 | BI40: 1.8250181e+09 | BJ40: 2.07235e+09 | BK40: 2.2209791e+09 | BL40: 2.2213014e+09 | BM40: 2.3267209e+09 | BN40: 2.5164984e+09 | BO40: 2.3826186e+09 | BP40: 2.5554921e+09
A41: Canada | B41: CAN | C41: GDP (current US$) | D41: NY.GDP.MKTP.CD | E41: 4.0563769e+10 | F41: 4.1038193e+10 | G41: 4.2336212e+10 | H41: 4.5140338e+10 | I41: 4.9503664e+10 | J41: 5.464941e+10 | K41: 6.1252415e+10 | L41: 6.5856924e+10 | M41: 7.2048833e+10 | N41: 7.9405011e+10 | O41: 8.8192258e+10 | P41: 9.9606455e+10 | Q41: 1.1346385e+11 | R41: 1.3176434e+11 | S41: 1.6094919e+11 | T41: 1.7441976e+11 | U41: 2.0727161e+11 | V41: 2.1232518e+11 | W41: 2.1936954e+11 | X41: 2.4389112e+11 | Y41: 2.7477657e+11 | Z41: 3.0724664e+11 | AA41: 3.1464781e+11 | AB41: 3.4186628e+11 | AC41: 3.567184e+11 | AD41: 3.6618601e+11 | AE41: 3.7900684e+11 | AF41: 4.3313424e+11 | AG41: 5.0938003e+11 | AH41: 5.6721199e+11 | AI41: 5.9607559e+11 | AJ41: 6.1252771e+11 | AK41: 5.9438736e+11 | AL41: 5.7905356e+11 | AM41: 5.7994435e+11 | AN41: 6.0596109e+11 | AO41: 6.3060799e+11 | AP41: 6.54987e+11 | AQ41: 634000000000 | AR41: 6.784122e+11 | AS41: 7.4477342e+11 | AT41: 7.3898179e+11 | AU41: 7.6064933e+11 | AV41: 8.9554065e+11 | AW41: 1.0266902e+12 | AX41: 1.1731086e+12 | AY41: 1.3192648e+12 | AZ41: 1.4688204e+12 | BA41: 1.5529897e+12 | BB41: 1.3746251e+12 | BC41: 1.6173434e+12 | BD41: 1.7933266e+12 | BE41: 1.8283665e+12 | BF41: 1.8465974e+12 | BG41: 1.8057499e+12 | BH41: 1.5565088e+12 | BI41: 1.5279947e+12 | BJ41: 1.6492656e+12 | BK41: 1.7253292e+12 | BL41: 1.7437252e+12 | BM41: 1.6556847e+12 | BN41: 2.0074722e+12 | BO41: 2.1614834e+12 | BP41: 2.1400856e+12
A42: Central Europe and the Baltics | B42: CEB | C42: GDP (current US$) | D42: NY.GDP.MKTP.CD | AI42: 2.7163712e+11 | AJ42: 2.4977019e+11 | AK42: 2.5644433e+11 | AL42: 2.6982667e+11 | AM42: 3.0802066e+11 | AN42: 3.9341819e+11 | AO42: 4.1619542e+11 | AP42: 4.1016936e+11 | AQ42: 4.4889452e+11 | AR42: 4.3506569e+11 | AS42: 4.2859756e+11 | AT42: 4.6861417e+11 | AU42: 5.2807438e+11 | AV42: 6.3439399e+11 | AW42: 7.6309045e+11 | AX42: 8.8607234e+11 | AY42: 1.0016372e+12 | AZ42: 1.2655657e+12 | BA42: 1.5307189e+12 | BB42: 1.2898536e+12 | BC42: 1.316548e+12 | BD42: 1.4547324e+12 | BE42: 1.3590529e+12 | BF42: 1.4175573e+12 | BG42: 1.463823e+12 | BH42: 1.2936233e+12 | BI42: 1.3168216e+12 | BJ42: 1.4615677e+12 | BK42: 1.6490142e+12 | BL42: 1.6748159e+12 | BM42: 1.6658175e+12 | BN42: 1.9082035e+12 | BO42: 1.943576e+12 | BP42: 2.2529709e+12
...

Sheet totalExpenditure
B1: Expenditure on defense | BA1: Expenditure on public order & safety | CZ1: GDP
A2: WORLD | B2: =B3*CZ2/CZ3 -> 5.2047727e+11 | C2: =C3*DA2/DA3 -> 5.6322895e+11 | D2: =D3*DB2/DB3 -> 6.3985668e+11 | E2: =E3*DC2/DC3 -> 6.9431913e+11 | F2: =F3*DD2/DD3 -> 6.9508391e+11 | G2: =G3*DE2/DE3 -> 7.5774891e+11 | H2: =H3*DF2/DF3 -> 8.544231e+11 | I2: =I3*DG2/DG3 -> 9.8909354e+11 | ... AZ2: =AZ3*EX2/EX3 -> 6.782079e+11 | BA2: =BA3*CZ2/CZ3 -> 9.8499748e+10 | BB2: =BB3*DA2/DA3 -> 1.1889353e+11 | BC2: =BC3*DB2/DB3 -> 1.4361942e+11 | BD2: =BD3*DC2/DC3 -> 1.6773888e+11 | BE2: =BE3*DD2/DD3 -> 1.7702512e+11 | BF2: =BF3*DE2/DE3 -> 1.9642617e+11 | BG2: =BG3*DF2/DF3 -> 2.2709209e+11 | BH2: =BH3*DG2/DG3 -> 2.6092652e+11 | ... CY2: =CY3*EX2/EX3 -> 1.5791109e+12 | CZ2: =gDP!Q265 -> 3.832675e+12 | DA2: =gDP!R265 -> 4.6624913e+12 | DB2: =gDP!S265 -> 5.3589336e+12 | DC2: =gDP!T265 -> 5.9906741e+12 | DD2: =gDP!U265 -> 6.5082763e+12 | DE2: =gDP!V265 -> 7.3567855e+12 | DF2: =gDP!W265 -> 8.7008463e+12 | DG2: =gDP!X265 -> 1.0113431e+13 | ... EX2: =gDP!BO265 -> 101225059591363
A3: SAMPLE TOTAL | B3: =SUMIF(CZ5:CZ270,">0",B5:B270) -> 173703138000 | C3: =SUMIF(DA5:DA270,">0",C5:C270) -> 172185420800 | D3: =SUMIF(DB5:DB270,">0",D5:D270) -> 184502014200 | E3: =SUMIF(DC5:DC270,">0",E5:E270) -> 195280373600 | F3: =SUMIF(DD5:DD270,">0",F5:F270) -> 200080401600 | G3: =SUMIF(DE5:DE270,">0",G5:G270) -> 2.1442808e+11 | H3: =SUMIF(DF5:DF270,">0",H5:H270) -> 2.3092702e+11 | I3: =SUMIF(DG5:DG270,">0",I5:I270) -> 2.5695317e+11 | ... AZ3: =SUMIF(EX5:EX270,">0",AZ5:AZ270) -> 1.4481939e+10 | BA3: =SUMIF(CZ5:CZ270,">0",BA5:BA270) -> 3.2873127e+10 | BB3: =SUMIF(DA5:DA270,">0",BB5:BB270) -> 36347088000 | BC3: =SUMIF(DB5:DB270,">0",BC5:BC270) -> 41412512400 | BD3: =SUMIF(DC5:DC270,">0",BD5:BD270) -> 4.7177312e+10 | BE3: =SUMIF(DD5:DD270,">0",BE5:BE270) -> 50956806400 | BF3: =SUMIF(DE5:DE270,">0",BF5:BF270) -> 5.5584754e+10 | BG3: =SUMIF(DF5:DF270,">0",BG5:BG270) -> 6.1376734e+10 | BH3: =SUMIF(DG5:DG270,">0",BH5:BH270) -> 67785191400 | ... CY3: =SUMIF(EX5:EX270,">0",CY5:CY270) -> 3.3719141e+10 | CZ3: {=SUM(_xlfn.IFNA(CZ5:CZ270,""))} -> 1279110000000 | DA3: {=SUM(_xlfn.IFNA(DA5:DA270,""))} -> 1425376000000 | DB3: {=SUM(_xlfn.IFNA(DB5:DB270,""))} -> 1545243000000 | DC3: {=SUM(_xlfn.IFNA(DC5:DC270,""))} -> 1684904000000 | DD3: {=SUM(_xlfn.IFNA(DD5:DD270,""))} -> 1873412000000 | DE3: {=SUM(_xlfn.IFNA(DE5:DE270,""))} -> 2081826000000 | DF3: {=SUM(_xlfn.IFNA(DF5:DF270,""))} -> 2351599000000 | DG3: {=SUM(_xlfn.IFNA(DG5:DG270,""))} -> 2627333000000 | ... EX3: {=SUM(_xlfn.IFNA(EX5:EX270,""))} -> 2.1614834e+12
A4: Country Code | B4: 1972 | C4: 1973 | D4: 1974 | E4: 1975 | F4: 1976 | G4: 1977 | H4: 1978 | I4: 1979 | J4: 1980 | K4: 1981 | L4: 1982 | M4: 1983 | N4: 1984 | O4: 1985 | P4: 1986 | Q4: 1987 | R4: 1988 | S4: 1989 | T4: 1990 | U4: 1991 | V4: 1992 | W4: 1993 | X4: 1994 | Y4: 1995 | Z4: 1996 | AA4: 1997 | AB4: 1998 | AC4: 1999 | AD4: 2000 | AE4: 2001 | AF4: 2002 | AG4: 2003 | AH4: 2004 | AI4: 2005 | AJ4: 2006 | AK4: 2007 | AL4: 2008 | AM4: 2009 | AN4: 2010 | AO4: 2011 | AP4: 2012 | AQ4: 2013 | AR4: 2014 | AS4: 2015 | AT4: 2016 | AU4: 2017 | AV4: 2018 | AW4: 2019 | AX4: 2020 | AY4: 2021 | AZ4: 2022 | BA4: 1972 | BB4: 1973 | BC4: 1974 | BD4: 1975 | BE4: 1976 | BF4: 1977 | BG4: 1978 | BH4: 1979 | BI4: 1980 | BJ4: 1981 | BK4: 1982 | BL4: 1983 | BM4: 1984 | BN4: 1985 | BO4: 1986 | BP4: 1987 | BQ4: 1988 | BR4: 1989 | BS4: 1990 | BT4: 1991 | BU4: 1992 | BV4: 1993 | BW4: 1994 | BX4: 1995 | BY4: 1996 | BZ4: 1997 | CA4: 1998 | CB4: 1999 | CC4: 2000 | CD4: 2001 | CE4: 2002 | CF4: 2003 | CG4: 2004 | CH4: 2005 | CI4: 2006 | CJ4: 2007 | CK4: 2008 | CL4: 2009 | CM4: 2010 | CN4: 2011 | CO4: 2012 | CP4: 2013 | CQ4: 2014 | CR4: 2015 | CS4: 2016 | CT4: 2017 | CU4: 2018 | CV4: 2019 | CW4: 2020 | CX4: 2021 | CY4: 2022 | CZ4: 1972 | DA4: 1973 | DB4: 1974 | DC4: 1975 | DD4: 1976 | DE4: 1977 | DF4: 1978 | DG4: 1979 | DH4: 1980 | DI4: 1981 | DJ4: 1982 | DK4: 1983 | DL4: 1984 | DM4: 1985 | DN4: 1986 | DO4: 1987 | DP4: 1988 | DQ4: 1989 | DR4: 1990 | DS4: 1991 | DT4: 1992 | DU4: 1993 | DV4: 1994 | DW4: 1995 | DX4: 1996 | DY4: 1997 | DZ4: 1998 | EA4: 1999 | EB4: 2000 | EC4: 2001 | ED4: 2002 | EE4: 2003 | EF4: 2004 | EG4: 2005 | EH4: 2006 | EI4: 2007 | EJ4: 2008 | EK4: 2009 | EL4: 2010 | EM4: 2011 | EN4: 2012 | EO4: 2013 | EP4: 2014 | EQ4: 2015 | ER4: 2016 | ES4: 2017 | ET4: 2018 | EU4: 2019 | EV4: 2020 | EW4: 2021 | EX4: 2022
A5: ABW | B5: =IF(INDEX([2]pivotTable!B$3:B$308,MATCH(totalExpenditure!$A5,[2]pivotTable!$A$3:$A$308,0))/100*INDEX(gDP!Q$6:Q$271,MATCH(totalExpenditure!$A5,gDP!$B$6:$B$271))=0,"",INDEX([2]pivotTable!B$3:B$308,MATCH(totalExpenditure!$A5,[2]pivotTable!$A$3:$A$308,0))/100*INDEX(gDP!Q$6:Q$271,MATCH(totalExpenditure!$A5,gDP!$B$6:$B$271))) -> #N/A | C5: =IF(INDEX([2]pivotTable!C$3:C$308,MATCH(totalExpenditure!$A5,[2]pivotTable!$A$3:$A$308,0))/100*INDEX(gDP!R$6:R$271,MATCH(totalExpenditure!$A5,gDP!$B$6:$B$271))=0,"",INDEX([2]pivotTable!C$3:C$308,MATCH(totalExpenditure!$A5,[2]pivotTable!$A$3:$A$308,0))/100*INDEX(gDP!R$6:R$271,MATCH(totalExpenditure!$A5,gDP!$B$6:$B$271))) -> #N/A | D5: =IF(INDEX([2]pivotTable!D$3:D$308,MATCH(totalExpenditure!$A5,[2]pivotTable!$A$3:$A$308,0))/100*INDEX(gDP!S$6:S$271,MATCH(totalExpenditure!$A5,gDP!$B$6:$B$271))=0,"",INDEX([2]pivotTable!D$3:D$308,MATCH(totalExpenditure!$A5,[2]pivotTable!$A$3:$A$308,0))/100*INDEX(gDP!S$6:S$271,MATCH(totalExpenditure!$A5,gDP!$B$6:$B$271))) -> #N/A | E5: =IF(INDEX([2]pivotTable!E$3:E$308,MATCH(totalExpenditure!$A5,[2]pivotTable!$A$3:$A$308,0))/100*INDEX(gDP!T$6:T$271,MATCH(totalExpenditure!$A5,gDP!$B$6:$B$271))=0,"",INDEX([2]pivotTable!E$3:E$308,MATCH(totalExpenditure!$A5,[2]pivotTable!$A$3:$A$308,0))/100*INDEX(gDP!T$6:T$271,MATCH(totalExpenditure!$A5,gDP!$B$6:$B$271))) -> #N/A | F5: =IF(INDEX([2]pivotTable!F$3:F$308,MATCH(totalExpenditure!$A5,[2]pivotTable!$A$3:$A$308,0))/100*INDEX(gDP!U$6:U$271,MATCH(totalExpenditure!$A5,gDP!$B$6:$B$271))=0,"",INDEX([2]pivotTable!F$3:F$308,MATCH(totalExpenditure!$A5,[2]pivotTable!$A$3:$A$308,0))/100*INDEX(gDP!U$6:U$271,MATCH(totalExpenditure!$A5,gDP!$B$6:$B$271))) -> #N/A | G5: =IF(INDEX([2]pivotTable!G$3:G$308,MATCH(totalExpenditure!$A5,[2]pivotTable!$A$3:$A$308,0))/100*INDEX(gDP!V$6:V$271,MATCH(totalExpenditure!$A5,gDP!$B$6:$B$271))=0,"",INDEX([2]pivotTable!G$3:G$308,MATCH(totalExpenditure!$A5,[2]pivotTable!$A$3:$A$308,0))/100*INDEX(gDP!V$6:V$271,MATCH(totalExpenditure!$A5,gDP!$B$6:$B$271))) -> #N/A | H5: =IF(INDEX([2]pivotTable!H$3:H$308,MATCH(totalExpenditure!$A5,[2]pivotTable!$A$3:$A$308,0))/100*INDEX(gDP!W$6:W$271,MATCH(totalExpenditure!$A5,gDP!$B$6:$B$271))=0,"",INDEX([2]pivotTable!H$3:H$308,MATCH(totalExpenditure!$A5,[2]pivotTable!$A$3:$A$308,0))/100*INDEX(gDP!W$6:W$271,MATCH(totalExpenditure!$A5,gDP!$B$6:$B$271))) -> #N/A | I5: =IF(INDEX([2]pivotTable!I$3:I$308,MATCH(totalExpenditure!$A5,[2]pivotTable!$A$3:$A$308,0))/100*INDEX(gDP!X$6:X$271,MATCH(totalExpenditure!$A5,gDP!$B$6:$B$271))=0,"",INDEX([2]pivotTable!I$3:I$308,MATCH(totalExpenditure!$A5,[2]pivotTable!$A$3:$A$308,0))/100*INDEX(gDP!X$6:X$271,MATCH(totalExpenditure!$A5,gDP!$B$6:$B$271))) -> #N/A | ... AZ5: =IF(INDEX([2]pivotTable!AZ$3:AZ$308,MATCH(totalExpenditure!$A5,[2]pivotTable!$A$3:$A$308,0))/100*INDEX(gDP!BO$6:BO$271,MATCH(totalExpenditure!$A5,gDP!$B$6:$B$271))=0,"",INDEX([2]pivotTable!AZ$3:AZ$308,MATCH(totalExpenditure!$A5,[2]pivotTable!$A$3:$A$308,0))/100*INDEX(gDP!BO$6:BO$271,MATCH(totalExpenditure!$A5,gDP!$B$6:$B$271))) -> #N/A | BA5: =IF(INDEX([2]pivotTable!B$310:B$615,MATCH(totalExpenditure!$A5,[2]pivotTable!$A$310:$A$615,0))/100*INDEX(gDP!Q$6:Q$271,MATCH(totalExpenditure!$A5,gDP!$B$6:$B$271))=0,"",INDEX([2]pivotTable!B$310:B$615,MATCH(totalExpenditure!$A5,[2]pivotTable!$A$310:$A$615,0))/100*INDEX(gDP!Q$6:Q$271,MATCH(totalExpenditure!$A5,gDP!$B$6:$B$271))) -> #N/A | BB5: =IF(INDEX([2]pivotTable!C$310:C$615,MATCH(totalExpenditure!$A5,[2]pivotTable!$A$310:$A$615,0))/100*INDEX(gDP!R$6:R$271,MATCH(totalExpenditure!$A5,gDP!$B$6:$B$271))=0,"",INDEX([2]pivotTable!C$310:C$615,MATCH(totalExpenditure!$A5,[2]pivotTable!$A$310:$A$615,0))/100*INDEX(gDP!R$6:R$271,MATCH(totalExpenditure!$A5,gDP!$B$6:$B$271))) -> #N/A | BC5: =IF(INDEX([2]pivotTable!D$310:D$615,MATCH(totalExpenditure!$A5,[2]pivotTable!$A$310:$A$615,0))/100*INDEX(gDP!S$6:S$271,MATCH(totalExpenditure!$A5,gDP!$B$6:$B$271))=0,"",INDEX([2]pivotTable!D$310:D$615,MATCH(totalExpenditure!$A5,[2]pivotTable!$A$310:$A$615,0))/100*INDEX(gDP!S$6:S$271,MATCH(totalExpenditure!$A5,gDP!$B$6:$B$271))) -> #N/A | BD5: =IF(INDEX([2]pivotTable!E$310:E$615,MATCH(totalExpenditure!$A5,[2]pivotTable!$A$310:$A$615,0))/100*INDEX(gDP!T$6:T$271,MATCH(totalExpenditure!$A5,gDP!$B$6:$B$271))=0,"",INDEX([2]pivotTable!E$310:E$615,MATCH(totalExpenditure!$A5,[2]pivotTable!$A$310:$A$615,0))/100*INDEX(gDP!T$6:T$271,MATCH(totalExpenditure!$A5,gDP!$B$6:$B$271))) -> #N/A | BE5: =IF(INDEX([2]pivotTable!F$310:F$615,MATCH(totalExpenditure!$A5,[2]pivotTable!$A$310:$A$615,0))/100*INDEX(gDP!U$6:U$271,MATCH(totalExpenditure!$A5,gDP!$B$6:$B$271))=0,"",INDEX([2]pivotTable!F$310:F$615,MATCH(totalExpenditure!$A5,[2]pivotTable!$A$310:$A$615,0))/100*INDEX(gDP!U$6:U$271,MATCH(totalExpenditure!$A5,gDP!$B$6:$B$271))) -> #N/A | BF5: =IF(INDEX([2]pivotTable!G$310:G$615,MATCH(totalExpenditure!$A5,[2]pivotTable!$A$310:$A$615,0))/100*INDEX(gDP!V$6:V$271,MATCH(totalExpenditure!$A5,gDP!$B$6:$B$271))=0,"",INDEX([2]pivotTable!G$310:G$615,MATCH(totalExpenditure!$A5,[2]pivotTable!$A$310:$A$615,0))/100*INDEX(gDP!V$6:V$271,MATCH(totalExpenditure!$A5,gDP!$B$6:$B$271))) -> #N/A | BG5: =IF(INDEX([2]pivotTable!H$310:H$615,MATCH(totalExpenditure!$A5,[2]pivotTable!$A$310:$A$615,0))/100*INDEX(gDP!W$6:W$271,MATCH(totalExpenditure!$A5,gDP!$B$6:$B$271))=0,"",INDEX([2]pivotTable!H$310:H$615,MATCH(totalExpenditure!$A5,[2]pivotTable!$A$310:$A$615,0))/100*INDEX(gDP!W$6:W$271,MATCH(totalExpenditure!$A5,gDP!$B$6:$B$271))) -> #N/A | BH5: =IF(INDEX([2]pivotTable!I$310:I$615,MATCH(totalExpenditure!$A5,[2]pivotTable!$A$310:$A$615,0))/100*INDEX(gDP!X$6:X$271,MATCH(totalExpenditure!$A5,gDP!$B$6:$B$271))=0,"",INDEX([2]pivotTable!I$310:I$615,MATCH(totalExpenditure!$A5,[2]pivotTable!$A$310:$A$615,0))/100*INDEX(gDP!X$6:X$271,MATCH(totalExpenditure!$A5,gDP!$B$6:$B$271))) -> #N/A | ... CY5: =IF(INDEX([2]pivotTable!AZ$310:AZ$615,MATCH(totalExpenditure!$A5,[2]pivotTable!$A$310:$A$615,0))/100*INDEX(gDP!BO$6:BO$271,MATCH(totalExpenditure!$A5,gDP!$B$6:$B$271))=0,"",INDEX([2]pivotTable!AZ$310:AZ$615,MATCH(totalExpenditure!$A5,[2]pivotTable!$A$310:$A$615,0))/100*INDEX(gDP!BO$6:BO$271,MATCH(totalExpenditure!$A5,gDP!$B$6:$B$271))) -> #N/A | CZ5: =IF(B5="","",IF(BA5="","",B5-B5+INDEX(gDP!Q$6:Q$271,MATCH(totalExpenditure!$A5,gDP!$B$6:$B$271)))) -> #N/A | DA5: =IF(C5="","",IF(BB5="","",C5-C5+INDEX(gDP!R$6:R$271,MATCH(totalExpenditure!$A5,gDP!$B$6:$B$271)))) -> #N/A | DB5: =IF(D5="","",IF(BC5="","",D5-D5+INDEX(gDP!S$6:S$271,MATCH(totalExpenditure!$A5,gDP!$B$6:$B$271)))) -> #N/A | DC5: =IF(E5="","",IF(BD5="","",E5-E5+INDEX(gDP!T$6:T$271,MATCH(totalExpenditure!$A5,gDP!$B$6:$B$271)))) -> #N/A | DD5: =IF(F5="","",IF(BE5="","",F5-F5+INDEX(gDP!U$6:U$271,MATCH(totalExpenditure!$A5,gDP!$B$6:$B$271)))) -> #N/A | DE5: =IF(G5="","",IF(BF5="","",G5-G5+INDEX(gDP!V$6:V$271,MATCH(totalExpenditure!$A5,gDP!$B$6:$B$271)))) -> #N/A | DF5: =IF(H5="","",IF(BG5="","",H5-H5+INDEX(gDP!W$6:W$271,MATCH(totalExpenditure!$A5,gDP!$B$6:$B$271)))) -> #N/A | DG5: =IF(I5="","",IF(BH5="","",I5-I5+INDEX(gDP!X$6:X$271,MATCH(totalExpenditure!$A5,gDP!$B$6:$B$271)))) -> #N/A | ... EX5: =IF(AZ5="","",IF(CY5="","",AZ5-AZ5+INDEX(gDP!BO$6:BO$271,MATCH(totalExpenditure!$A5,gDP!$B$6:$B$271)))) -> #N/A
